---
title: 'Try-Except Blocks in Python'
linkTitle: 'Try-Except Blocks in Python'
weight: 2
---

In programming, errors and exceptions are inevitable. Rather than letting them crash your program, Python provides a powerful mechanism called "exception handling" that allows you to catch and respond to errors gracefully. The primary tool for this is the try-except block.

## Understanding Exceptions

Before diving into try-except blocks, it's important to understand what exceptions are. An exception is an event that occurs during the execution of a program that disrupts the normal flow of instructions. When Python encounters an error, it creates an exception object containing information about the error.

Common exceptions include:

- `SyntaxError`: Occurs when Python can't parse your code (not catchable with try-except)
- `NameError`: Occurs when you try to use a variable that doesn't exist
- `TypeError`: Occurs when an operation is performed on an object of inappropriate type
- `ValueError`: Occurs when a function receives an argument of the correct type but inappropriate value
- `IndexError`: Occurs when you try to access an index that's outside the bounds of a sequence
- `KeyError`: Occurs when you try to access a dictionary key that doesn't exist
- `FileNotFoundError`: Occurs when you try to open a file that doesn't exist
- `ZeroDivisionError`: Occurs when you try to divide by zero

## Basic Try-Except Structure

The basic syntax of a try-except block is:

```python
try:
    # Code that might raise an exception
    # This is the "protected" block
except:
    # Code that executes if an exception occurs
    # This is the "handler" block
```

Here's a simple example:

```python
try:
    num = int(input("Enter a number: "))
    print(f"You entered: {num}")
except:
    print("That's not a valid number!")
```

In this example:
1. The code in the `try` block attempts to convert user input to an integer
2. If the conversion succeeds, it prints the number
3. If the conversion fails (e.g., if the user enters "abc"), Python raises a `ValueError`
4. The `except` block catches the exception and displays a friendly error message

**Important:**
Using a bare `except:` clause (without specifying an exception type) catches all exceptions. This is generally not recommended as it can hide unexpected errors and make debugging difficult.

## Catching Specific Exceptions

It's better practice to catch specific exceptions:

```python
try:
    num = int(input("Enter a number: "))
    result = 10 / num
    print(f"10 divided by {num} is {result}")
except ValueError:
    print("That's not a valid number!")
except ZeroDivisionError:
    print("You can't divide by zero!")
```

This approach allows you to handle different types of errors in different ways. Python checks each `except` clause in order and executes the first one that matches the raised exception.

## Catching Multiple Exceptions

You can also catch multiple exception types in a single `except` clause:

```python
try:
    num = int(input("Enter a number: "))
    result = 10 / num
    print(f"10 divided by {num} is {result}")
except (ValueError, ZeroDivisionError):
    print("Invalid input: Please enter a non-zero number.")
```

This is useful when you want to handle different exceptions in the same way.

## Getting Exception Information

You can capture the exception object itself using the `as` keyword:

```python
try:
    with open("nonexistent_file.txt", "r") as file:
        content = file.read()
except FileNotFoundError as e:
    print(f"Error: {e}")
    print(f"Error type: {type(e).__name__}")
```

The exception object contains useful information about what went wrong.

## The `else` Clause

The `else` clause in a try-except block executes if no exceptions occur:

```python
try:
    num = int(input("Enter a number: "))
    result = 10 / num
except ValueError:
    print("That's not a valid number!")
except ZeroDivisionError:
    print("You can't divide by zero!")
else:
    print(f"10 divided by {num} is {result}")
    print("No exceptions occurred!")
```

Using `else` separates the exception-handling code from the code that should run when everything succeeds, making your program easier to understand.

## The `finally` Clause

The `finally` clause executes regardless of whether an exception occurred:

```python
try:
    file = open("data.txt", "r")
    content = file.read()
except FileNotFoundError:
    print("The file was not found.")
finally:
    # This executes no matter what
    try:
        file.close()
    except:
        pass  # If file wasn't opened, file.close() would raise an exception
    print("File operation attempted.")
```

The `finally` clause is especially useful for cleanup operations that should always occur, like closing files or network connections, regardless of whether an exception happened.

**Note:**
Using context managers (the `with` statement) is often a cleaner alternative to `finally` for resource cleanup:

```python
try:
    with open("data.txt", "r") as file:  # File automatically closes when block exits
        content = file.read()
except FileNotFoundError:
    print("The file was not found.")
```

## Complete Structure

The complete try-except structure can include all of these components:

```python
try:
    # Code that might raise an exception
except ExceptionType1:
    # Handle ExceptionType1
except ExceptionType2:
    # Handle ExceptionType2
except:
    # Handle any other exceptions
else:
    # Execute if no exceptions occurred
finally:
    # Always execute this block
```

## Raising Exceptions

Sometimes, you need to raise exceptions yourself:

```python
def divide(a, b):
    if b == 0:
        raise ValueError("Cannot divide by zero")
    return a / b

try:
    result = divide(10, 0)
except ValueError as e:
    print(f"Error: {e}")
```

You can raise built-in exceptions or create custom ones by subclassing `Exception`.

## Creating Custom Exceptions

For domain-specific errors, it's often useful to create custom exceptions:

```python
class InsufficientFundsError(Exception):
    """Raised when a withdrawal exceeds the available balance."""
    pass

class BankAccount:
    def __init__(self, balance=0):
        self.balance = balance
        
    def withdraw(self, amount):
        if amount > self.balance:
            raise InsufficientFundsError(f"Cannot withdraw ${amount}. Only ${self.balance} available.")
        self.balance -= amount
        return self.balance

# Using the custom exception
account = BankAccount(100)
try:
    account.withdraw(150)
except InsufficientFundsError as e:
    print(f"Transaction failed: {e}")
```

Custom exceptions make your code more readable and help communicate the specific problem that occurred.

## Re-raising Exceptions

Sometimes you want to catch an exception, perform some action, and then re-raise it:

```python
try:
    # Some code that might raise an exception
    x = 1 / 0
except ZeroDivisionError:
    print("Logging the zero division error")
    raise  # Re-raises the most recent exception
```

This is useful when you need to perform some cleanup or logging but still want the exception to propagate to the caller.

## The `assert` Statement

Python's `assert` statement provides a simple way to test conditions during development:

```python
def calculate_average(numbers):
    assert len(numbers) > 0, "Cannot calculate average of empty list"
    return sum(numbers) / len(numbers)

try:
    avg = calculate_average([])
except AssertionError as e:
    print(f"Error: {e}")
```

Assertions are primarily used for debugging and should not be used to handle runtime errors in production code.

## Practical Examples

### Example 1: Basic File Processing

```python
def read_file_content(filename):
    """Read and return the content of a file, handling potential errors."""
    try:
        with open(filename, 'r') as file:
            content = file.read()
        return content
    except FileNotFoundError:
        print(f"Error: The file '{filename}' was not found.")
    except PermissionError:
        print(f"Error: You don't have permission to read '{filename}'.")
    except Exception as e:
        print(f"An unexpected error occurred: {e}")
    
    # If any exception occurred, return None
    return None

# Test the function
content = read_file_content("example.txt")
if content:
    print(f"File content: {content}")
else:
    print("Could not read the file.")
```

### Example 2: User Input Validation

```python
def get_positive_integer(prompt):
    """Get a positive integer from the user with input validation."""
    while True:
        try:
            value = int(input(prompt))
            if value <= 0:
                print("Please enter a positive number.")
                continue
            return value
        except ValueError:
            print("Invalid input. Please enter a number.")

# Test the function
age = get_positive_integer("Enter your age: ")
print(f"Your age is {age}.")
```

### Example 3: Safe Dictionary Access

```python
def safe_get(dictionary, key, default=None):
    """Safely get a value from a dictionary with a default if the key doesn't exist."""
    try:
        return dictionary[key]
    except KeyError:
        return default

# Test the function
user_data = {"name": "John", "age": 30}
print(safe_get(user_data, "name"))        # John
print(safe_get(user_data, "email"))       # None
print(safe_get(user_data, "email", "N/A")) # N/A
```

### Example 4: Database Connection with Error Handling

```python
import sqlite3

def execute_query(database_path, query, parameters=()):
    """Execute a query on an SQLite database with comprehensive error handling."""
    connection = None
    try:
        connection = sqlite3.connect(database_path)
        cursor = connection.cursor()
        cursor.execute(query, parameters)
        connection.commit()
        return cursor.fetchall()
    except sqlite3.OperationalError as e:
        print(f"Database operation failed: {e}")
    except sqlite3.IntegrityError as e:
        print(f"Database integrity error: {e}")
    except Exception as e:
        print(f"Unexpected error: {e}")
    finally:
        if connection:
            connection.close()
    return None

# Example usage
results = execute_query("users.db", "SELECT * FROM users WHERE age > ?", (25,))
if results:
    for row in results:
        print(row)
else:
    print("Query failed or returned no results.")
```

## Best Practices for Exception Handling

### 1. Be Specific About Which Exceptions to Catch

```python
# Too broad - might hide bugs
try:
    # Some code
except:
    # Handle any exception

# Better - catch specific exceptions
try:
    # Some code
except ValueError:
    # Handle ValueError
except ZeroDivisionError:
    # Handle ZeroDivisionError
```

### 2. Keep the Try Block as Small as Possible

```python
# Not recommended - try block is too large
try:
    file = open("data.txt", "r")
    content = file.read()
    numbers = [int(x) for x in content.split()]
    average = sum(numbers) / len(numbers)
    print(f"Average: {average}")
    file.close()
except:
    print("An error occurred")

# Better - separate try blocks for different operations
try:
    file = open("data.txt", "r")
except FileNotFoundError:
    print("File not found")
    exit()

try:
    content = file.read()
finally:
    file.close()

try:
    numbers = [int(x) for x in content.split()]
    average = sum(numbers) / len(numbers)
    print(f"Average: {average}")
except ValueError:
    print("File contains non-numeric data")
except ZeroDivisionError:
    print("File contains no data")
```

### 3. Avoid Silencing Exceptions Without Good Reason

```python
# Bad practice - silently ignoring exceptions
try:
    some_risky_function()
except:
    pass  # Ignores all exceptions

# Better - handle or log the exception
try:
    some_risky_function()
except Exception as e:
    print(f"An error occurred: {e}")
    # Or log the error for later investigation
    logging.error(f"Error in some_risky_function: {e}")
```

### 4. Use Context Managers for Resource Management

```python
# Not recommended
file = open("data.txt", "r")
try:
    content = file.read()
finally:
    file.close()

# Better - using a context manager
try:
    with open("data.txt", "r") as file:
        content = file.read()
except FileNotFoundError:
    print("File not found")
```

### 5. Clean Up Resources in the `finally` Block

```python
connection = None
try:
    connection = create_database_connection()
    # Use the connection
except ConnectionError:
    print("Failed to connect to the database")
finally:
    if connection:
        connection.close()
```

### 6. Don't Use Exceptions for Flow Control

```python
# Not recommended - using exceptions for normal flow control
try:
    result = dictionary[key]
except KeyError:
    result = default_value

# Better - use a conditional
result = dictionary.get(key, default_value)

# Not recommended
try:
    value = int(input("Enter a number: "))
except ValueError:
    value = 0

# Better
user_input = input("Enter a number: ")
if user_input.isdigit():
    value = int(user_input)
else:
    value = 0
```

However, there are cases where using exceptions for control flow is the "Pythonic" way, particularly when dealing with the "easier to ask forgiveness than permission" (EAFP) coding style:

```python
# EAFP style (Pythonic)
try:
    return mapping[key]
except KeyError:
    return default_value

# Look before you leap style (less Pythonic in this case)
if key in mapping:
    return mapping[key]
else:
    return default_value
```

### 7. Use Logging Instead of Print Statements for Errors

```python
import logging

# Configure logging
logging.basicConfig(
    level=logging.INFO,
    format='%(asctime)s - %(name)s - %(levelname)s - %(message)s',
    filename='app.log'
)

try:
    # Some risky operation
    result = 10 / 0
except ZeroDivisionError:
    # Log the error instead of just printing it
    logging.error("Division by zero attempted")
```

## Common Exception Handling Patterns

### Pattern 1: Retry Logic

```python
import time
import random

def make_api_request(endpoint):
    """Simulate an API request that might fail temporarily."""
    if random.random() < 0.7:  # 70% chance of failure
        raise ConnectionError("API connection failed")
    return {"status": "success", "data": "Some data"}

def get_api_data(endpoint, max_retries=3, delay=1):
    """Get data from an API with retry logic."""
    retries = 0
    while retries < max_retries:
        try:
            return make_api_request(endpoint)
        except ConnectionError as e:
            retries += 1
            if retries == max_retries:
                print(f"Failed after {max_retries} attempts. Error: {e}")
                return None
            print(f"Attempt {retries} failed. Retrying in {delay} seconds...")
            time.sleep(delay)
            delay *= 2  # Exponential backoff

# Test the function
result = get_api_data("/users")
if result:
    print(f"API request succeeded: {result}")
```

### Pattern 2: Default Value Pattern

```python
def get_config_value(config_dict, key, default=None):
    """
    Get a configuration value with a default if it doesn't exist
    or has the wrong type.
    """
    try:
        return config_dict[key]
    except KeyError:
        return default
    except TypeError:
        # This could happen if config_dict is not actually a dictionary
        return default

# Test the function
config = {"port": 8080, "host": "localhost"}
print(get_config_value(config, "port"))        # 8080
print(get_config_value(config, "debug", False)) # False
print(get_config_value(None, "anything", "default"))  # "default"
```

### Pattern 3: Cleanup Pattern

```python
def process_file(filename):
    """Process a file and ensure it gets closed even if errors occur."""
    temp_file = None
    try:
        # Open the original file
        with open(filename, 'r') as file:
            content = file.read()
        
        # Create a temporary file for processing
        temp_filename = filename + ".tmp"
        temp_file = open(temp_filename, 'w')
        
        # Process the content and write to temp file
        processed_content = content.replace('old', 'new')
        temp_file.write(processed_content)
        
        return True
    except FileNotFoundError:
        print(f"The file {filename} was not found.")
        return False
    except IOError as e:
        print(f"I/O error occurred: {e}")
        return False
    finally:
        # Make sure the temp file is closed
        if temp_file:
            temp_file.close()
```

### Pattern 4: Context Manager Pattern

```python
class TempFile:
    """A context manager for temporary files."""
    
    def __init__(self, filename):
        self.filename = filename
        self.file = None
    
    def __enter__(self):
        self.file = open(self.filename, 'w')
        return self.file
    
    def __exit__(self, exc_type, exc_val, exc_tb):
        if self.file:
            self.file.close()
        
        # If an exception occurred, log it but don't suppress it
        if exc_type is not None:
            print(f"An error occurred: {exc_type.__name__}: {exc_val}")
        
        # Returning False means any exceptions will be propagated
        return False

# Using our custom context manager
try:
    with TempFile("temp.txt") as file:
        file.write("Hello, World!")
        # Let's simulate an error
        if random.random() < 0.5:
            raise RuntimeError("Random error occurred")
except RuntimeError:
    print("Handled the runtime error outside the context manager")
```

## Debugging with Try-Except

While try-except blocks are primarily for error handling, they can also help with debugging. Here are some techniques:

### Using `print` for Poor Man's Debugging

```python
def complex_function(a, b, c):
    """A function with multiple steps that might fail."""
    try:
        print(f"Starting with values: a={a}, b={b}, c={c}")
        
        step1 = a / b
        print(f"After step 1: {step1}")
        
        step2 = step1 + c
        print(f"After step 2: {step2}")
        
        step3 = step2 ** 2
        print(f"After step 3: {step3}")
        
        return step3
    except Exception as e:
        print(f"Error occurred: {type(e).__name__}: {e}")
        raise  # Re-raise the exception after logging it
```

### Using the Traceback Module

```python
import traceback

def function_with_error():
    """A function that will raise an error."""
    return 1 / 0

try:
    function_with_error()
except Exception as e:
    print(f"An error occurred: {e}")
    traceback.print_exc()  # Print the full traceback
```

## Exercises

**Exercise 1:** Write a function called `safe_division` that takes two parameters and returns their division. Your function should handle cases where the second parameter is zero or either parameter is not a number. Return `None` in case of errors.

**Exercise 2:** Create a program that reads a CSV file, converts each line into a list of integers, and calculates the sum of each line. Use exception handling to deal with lines that contain non-numeric values or files that don't exist.

**Exercise 3:** Write a function called `get_element` that takes a list, an index, and a default value. It should return the element at the given index or the default value if the index is out of range.

**Exercise 4:** Create a context manager called `Timer` that measures and prints the time taken to execute the code inside the `with` block. Use the `time` module to measure execution time.

**Hint for Exercise 1:** 
```python
def safe_division(a, b):
    try:
        return a / b
    except ZeroDivisionError:
        print("Error: Division by zero.")
        return None
    except TypeError:
        print("Error: Inputs must be numbers.")
        return None
```

In the next section, we'll explore raising exceptions, which allows you to create and raise your own exceptions when specific conditions are met in your code.